Workbook
Name gen: #REF!
Name initCap: #REF!
Name initCap: #REF!
Name invCost: #REF!
Name invCost: #REF!
Name line: [1]Lifetime!$A$3:$C$8
Name line2: [1]Lifetime!$A$3:$C$5
Name maxBuiltCap: #REF!
Name maxBuiltCap: #REF!
Name maxInstalledCap: #REF!
Name maxInstalledCap: #REF!
Name stor: Lifetime!$A$3:$B$5

Sheet InitialPowerCapacity
A1: Source: STATISTICAL FACTSHEET 2018 (ENTSO-E)
A2: Description: Initial capacity in each investment period. NB! No retirement (default: 0) | G2: Hydro capacity shared 50/50 between pumped and regulated
A3: Nodes | B3: StorageTypes | C3: Period | D3: InitialPowerCapacity | G3: Partly non-renewable according to ENTSO-E
A4: Austria | B4: Hydro Pump Storage | C4: 1 | D4: =8436/2 -> 4218
A5: Bosnia H | B5: Hydro Pump Storage | C5: 1 | D5: 335
A6: Belgium | B6: Hydro Pump Storage | C6: 1 | D6: 1308
A7: Bulgaria | B7: Hydro Pump Storage | C7: 1 | D7: =864+133+57 -> 1054
A8: Switzerland | B8: Hydro Pump Storage | C8: 1 | D8: 1864
A9: Czech R | B9: Hydro Pump Storage | C9: 1 | D9: 1172
A10: Germany | B10: Hydro Pump Storage | C10: 1 | D10: 5294
A11: Spain | B11: Hydro Pump Storage | C11: 1 | D11: =3329+3073 -> 6402
A12: France | B12: Hydro Pump Storage | C12: 1 | D12: 2455
A13: Great Brit. | B13: Hydro Pump Storage | C13: 1 | D13: 2744
A14: Greece | B14: Hydro Pump Storage | C14: 1 | D14: 699
A15: Croatia | B15: Hydro Pump Storage | C15: 1 | D15: 281
A16: Hungary | B16: Hydro Pump Storage | C16: 1 | D16: 28
A17: Ireland | B17: Hydro Pump Storage | C17: 1 | D17: 292
A18: Italy | B18: Hydro Pump Storage | C18: 1 | D18: =4753+4015 -> 8768
A19: Lithuania | B19: Hydro Pump Storage | C19: 1 | D19: 900
A20: Luxemb. | B20: Hydro Pump Storage | C20: 1 | D20: 1296
A33: Austria | B33: Hydro Pump Storage | C33: 2 | D33: =8436/2 -> 4218
A34: Bosnia H | B34: Hydro Pump Storage | C34: 2 | D34: 335
A35: Belgium | B35: Hydro Pump Storage | C35: 2 | D35: 1308
A36: Bulgaria | B36: Hydro Pump Storage | C36: 2 | D36: =864+133+57 -> 1054
A37: Switzerland | B37: Hydro Pump Storage | C37: 2 | D37: 1864
A38: Czech R | B38: Hydro Pump Storage | C38: 2 | D38: 1172
A39: Germany | B39: Hydro Pump Storage | C39: 2 | D39: 5294
A40: Spain | B40: Hydro Pump Storage | C40: 2 | D40: =3329+3073 -> 6402
A41: France | B41: Hydro Pump Storage | C41: 2 | D41: 2455
A42: Great Brit. | B42: Hydro Pump Storage | C42: 2 | D42: 2744
A43: Greece | B43: Hydro Pump Storage | C43: 2 | D43: 699
A44: Croatia | B44: Hydro Pump Storage | C44: 2 | D44: 281
A45: Hungary | B45: Hydro Pump Storage | C45: 2 | D45: 28
A46: Ireland | B46: Hydro Pump Storage | C46: 2 | D46: 292
A47: Italy | B47: Hydro Pump Storage | C47: 2 | D47: =4753+4015 -> 8768
A48: Lithuania | B48: Hydro Pump Storage | C48: 2 | D48: 900
A49: Luxemb. | B49: Hydro Pump Storage | C49: 2 | D49: 1296
A61: Austria | B61: Hydro Pump Storage | C61: 3 | D61: =8436/2 -> 4218
A62: Bosnia H | B62: Hydro Pump Storage | C62: 3 | D62: 335
A63: Belgium | B63: Hydro Pump Storage | C63: 3 | D63: 1308
...

Sheet PowerCapitalCost
A1: Source: Battery cost medish (Cole et al 2016) 2014$/kWh
A2: Description: Capital cost for investing in power of storage (default: 0)
A3: StorageTypes | B3: Period | C3: PowerCapitalCost in euro per kW
A4: Hydro Pump Storage | B4: 1 | C4: 1000
A5: Hydro Pump Storage | B5: 2 | C5: 1000
A6: Hydro Pump Storage | B6: 3 | C6: 1000
A7: Hydro Pump Storage | B7: 4 | C7: 1000
A8: Hydro Pump Storage | B8: 5 | C8: 1000
A9: Hydro Pump Storage | B9: 6 | C9: 1000
A10: Hydro Pump Storage | B10: 7 | C10: 1000
A11: Hydro Pump Storage | B11: 8 | C11: 1000
A12: Li-Ion_BESS | B12: 1 | C12: 0
A13: Li-Ion_BESS | B13: 2 | C13: 0
A14: Li-Ion_BESS | B14: 3 | C14: 0
A15: Li-Ion_BESS | B15: 4 | C15: 0
... A19: Li-Ion_BESS | B19: 8 | C19: 0

Sheet PowerFixedOMCost
A1: Source: Battery cost medish (Cole et al 2016) 2014$/kWh
A2: Description: Fixed O&M cost for investing in power of storage (default: 0)
A3: StorageTypes | B3: Period | C3: PowerFixedOMCost in euro per kW
A4: Hydro Pump Storage | B4: 1 | C4: 0
A5: Hydro Pump Storage | B5: 2 | C5: 0
A6: Hydro Pump Storage | B6: 3 | C6: 0
A7: Hydro Pump Storage | B7: 4 | C7: 0
A8: Hydro Pump Storage | B8: 5 | C8: 0
A9: Hydro Pump Storage | B9: 6 | C9: 0
A10: Hydro Pump Storage | B10: 7 | C10: 0
A11: Hydro Pump Storage | B11: 8 | C11: 0
A12: Li-Ion_BESS | B12: 1 | C12: 6.7049808
A13: Li-Ion_BESS | B13: 2 | C13: 5.8201058
A14: Li-Ion_BESS | B14: 3 | C14: 5.1587302
A15: Li-Ion_BESS | B15: 4 | C15: 5.1587302
... A19: Li-Ion_BESS | B19: 8 | C19: 5.1587302

Sheet PowerMaxBuiltCapacity
A1: Source: Assumed
A2: Description: Maximum capacity expansion of power of storage type in one node and period (default: 500 000)
A3: Nodes | B3: StorageTypes | C3: Period | D3: PowerMaxBuiltCapacity
A4: Austria | B4: Hydro Pump Storage | C4: 1 | D4: 500000
A5: Bosnia H | B5: Hydro Pump Storage | C5: 1 | D5: 500000
A6: Belgium | B6: Hydro Pump Storage | C6: 1 | D6: 500000
A7: Bulgaria | B7: Hydro Pump Storage | C7: 1 | D7: 500000
A8: Switzerland | B8: Hydro Pump Storage | C8: 1 | D8: 500000
A9: Czech R | B9: Hydro Pump Storage | C9: 1 | D9: 500000
A10: Germany | B10: Hydro Pump Storage | C10: 1 | D10: 500000
A11: Spain | B11: Hydro Pump Storage | C11: 1 | D11: 500000
A12: Finland | B12: Hydro Pump Storage | C12: 1 | D12: 500000
A13: France | B13: Hydro Pump Storage | C13: 1 | D13: 500000
A14: Great Brit. | B14: Hydro Pump Storage | C14: 1 | D14: 500000
A15: Greece | B15: Hydro Pump Storage | C15: 1 | D15: 500000
... A53: Luxemb. | B53: Li-Ion_BESS | C53: 1 | D53: 500000

Sheet PowerMaxInstalledCapacity
A1: Source: Eurelectric, ISO, ENTSO-E, ZEP (+50% of installed capacity)
A2: Description: Maximum installed capacity in all time periods of power of storage type (default: 0)
A3: Nodes | B3: StorageTypes | C3: PowerMaxInstalledCapacity
A4: Austria | B4: Hydro Pump Storage | C4: =InitialPowerCapacity!D4*1.5 -> 6327
A5: Bosnia H | B5: Hydro Pump Storage | C5: =InitialPowerCapacity!D5*1.5 -> 502.5
A6: Belgium | B6: Hydro Pump Storage | C6: =InitialPowerCapacity!D6*1.5 -> 1962
A7: Bulgaria | B7: Hydro Pump Storage | C7: =InitialPowerCapacity!D7*1.5 -> 1581
A8: Switzerland | B8: Hydro Pump Storage | C8: =InitialPowerCapacity!D8*1.5 -> 2796
A9: Czech R | B9: Hydro Pump Storage | C9: =InitialPowerCapacity!D9*1.5 -> 1758
A10: Germany | B10: Hydro Pump Storage | C10: =InitialPowerCapacity!D10*1.5 -> 7941
A11: Spain | B11: Hydro Pump Storage | C11: =InitialPowerCapacity!D11*1.5 -> 9603
A12: France | B12: Hydro Pump Storage | C12: =InitialPowerCapacity!D12*1.5 -> 3682.5
A13: Great Brit. | B13: Hydro Pump Storage | C13: =InitialPowerCapacity!D13*1.5 -> 4116
A14: Greece | B14: Hydro Pump Storage | C14: =InitialPowerCapacity!D14*1.5 -> 1048.5
A15: Croatia | B15: Hydro Pump Storage | C15: =InitialPowerCapacity!D15*1.5 -> 421.5
... A20: Luxemb. | B20: Hydro Pump Storage | C20: =InitialPowerCapacity!D20*1.5 -> 1944
A33: Austria | B33: Li-Ion_BESS | C33: 20000000
A34: Bosnia H | B34: Li-Ion_BESS | C34: 20000000
A35: Belgium | B35: Li-Ion_BESS | C35: 20000000
A36: Bulgaria | B36: Li-Ion_BESS | C36: 20000000
A37: Switzerland | B37: Li-Ion_BESS | C37: 20000000
A38: Czech R | B38: Li-Ion_BESS | C38: 20000000
A39: Germany | B39: Li-Ion_BESS | C39: 20000000
A40: Denmark | B40: Li-Ion_BESS | C40: 20000000
A41: Estonia | B41: Li-Ion_BESS | C41: 20000000
A42: Spain | B42: Li-Ion_BESS | C42: 20000000
A43: Finland | B43: Li-Ion_BESS | C43: 20000000
A44: France | B44: Li-Ion_BESS | C44: 20000000
... A52: Luxemb. | B52: Li-Ion_BESS | C52: 20000000

Sheet EnergyCapitalCost
A1: Source: Battery cost medish (Cole et al 2016) 2014$/kWh
A2: Description: Capital cost for investing in energy storage capacity (default: 0)
A3: StorageTypes | B3: Period | C3: EnergyCapitalCost in euro per kWh
A4: Hydro Pump Storage | B4: 1 | C4: 100
A5: Hydro Pump Storage | B5: 2 | C5: 100
A6: Hydro Pump Storage | B6: 3 | C6: 100
A7: Hydro Pump Storage | B7: 4 | C7: 100
A8: Hydro Pump Storage | B8: 5 | C8: 100
A9: Hydro Pump Storage | B9: 6 | C9: 100
A10: Hydro Pump Storage | B10: 7 | C10: 100
A11: Hydro Pump Storage | B11: 8 | C11: 100
A12: Li-Ion_BESS | B12: 1 | C12: 246.30542
A13: Li-Ion_BESS | B13: 2 | C13: 198.4127
A14: Li-Ion_BESS | B14: 3 | C14: 198.4127
A15: Li-Ion_BESS | B15: 4 | C15: 198.4127
... A19: Li-Ion_BESS | B19: 8 | C19: 198.4127

Sheet EnergyFixedOMCost
A1: Source: Battery cost medish (Cole et al 2016) 2014$/kWh
A2: Description: Fixed O&M cost for investing in energy storage capacity (default: 0)
A3: StorageTypes | B3: Period | C3: EnergyFixedOMCost in euro per kWh
A4: Hydro Pump Storage | B4: 1 | C4: 0
A5: Hydro Pump Storage | B5: 2 | C5: 0
A6: Hydro Pump Storage | B6: 3 | C6: 0
A7: Hydro Pump Storage | B7: 4 | C7: 0
A8: Hydro Pump Storage | B8: 5 | C8: 0
A9: Hydro Pump Storage | B9: 6 | C9: 0
A10: Hydro Pump Storage | B10: 7 | C10: 0
A11: Hydro Pump Storage | B11: 8 | C11: 0
A12: Li-Ion_BESS | B12: 1 | C12: 0
A13: Li-Ion_BESS | B13: 2 | C13: 0
A14: Li-Ion_BESS | B14: 3 | C14: 0
A15: Li-Ion_BESS | B15: 4 | C15: 0
... A19: Li-Ion_BESS | B19: 8 | C19: 0

Sheet EnergyInitialCapacity
A1: Source: Eurelectric, ISO, ENTSO-E, ZEP
A2: Description: Initial capacity in node and investment period of a storage type. NB! No retirement (default: 0)
A3: Nodes | B3: StorageTypes | C3: Period | D3: EnergyInitialCapacity
A4: Austria | B4: Hydro Pump Storage | C4: 1 | D4: 124704
A5: Bosnia H | B5: Hydro Pump Storage | C5: 1 | D5: 2199.34
A6: Belgium | B6: Hydro Pump Storage | C6: 1 | D6: 7762.5
A7: Bulgaria | B7: Hydro Pump Storage | C7: 1 | D7: 1499.2
A8: Switzerland | B8: Hydro Pump Storage | C8: 1 | D8: 368989
A9: Czech R | B9: Hydro Pump Storage | C9: 1 | D9: 6723.5
A10: Germany | B10: Hydro Pump Storage | C10: 1 | D10: 38626
A11: Spain | B11: Hydro Pump Storage | C11: 1 | D11: 1530150.9
A12: France | B12: Hydro Pump Storage | C12: 1 | D12: 184296
A13: Great Brit. | B13: Hydro Pump Storage | C13: 1 | D13: 33432
A14: Greece | B14: Hydro Pump Storage | C14: 1 | D14: 21190.44
A15: Croatia | B15: Hydro Pump Storage | C15: 1 | D15: 21190.44
... A217: Luxemb. | B217: Hydro Pump Storage | C217: 8 | D217: 6120

Sheet EnergyMaxBuiltCapacity
A1: Source: Assumed
A2: Description: Maximum capacity expansion of energy of storage type in one node and period (default: 500 000)
A3: Nodes | B3: StorageTypes | C3: Period | D3: EnergyMaxBuiltCapacity
A4: Austria | B4: Hydro Pump Storage | C4: 1 | D4: 500000
A5: Bosnia H | B5: Hydro Pump Storage | C5: 1 | D5: 500000
A6: Belgium | B6: Hydro Pump Storage | C6: 1 | D6: 500000
A7: Bulgaria | B7: Hydro Pump Storage | C7: 1 | D7: 500000
A8: Switzerland | B8: Hydro Pump Storage | C8: 1 | D8: 500000
A9: Czech R | B9: Hydro Pump Storage | C9: 1 | D9: 500000
A10: Germany | B10: Hydro Pump Storage | C10: 1 | D10: 500000
A11: Spain | B11: Hydro Pump Storage | C11: 1 | D11: 500000
A12: Finland | B12: Hydro Pump Storage | C12: 1 | D12: 500000
A13: France | B13: Hydro Pump Storage | C13: 1 | D13: 500000
A14: Great Brit. | B14: Hydro Pump Storage | C14: 1 | D14: 500000
A15: Greece | B15: Hydro Pump Storage | C15: 1 | D15: 500000
... A53: Luxemb. | B53: Li-Ion_BESS | C53: 1 | D53: 500000

Sheet EnergyMaxInstalledCapacity
A1: Source: Eurelectric: 'Hydro in Europe: Powering Renewables' (+10% of existing capacity)
A2: Description: Maximum installed capacity in all time periods of energy of storage type (default: 0)
A3: Nodes | B3: StorageTypes | C3: EnergyMaxInstalledCapacity
A4: Austria | B4: Hydro Pump Storage | C4: =EnergyInitialCapacity!D4*1.1 -> 137174.4
A5: Bosnia H | B5: Hydro Pump Storage | C5: =EnergyInitialCapacity!D5*1.1 -> 2419.274
A6: Belgium | B6: Hydro Pump Storage | C6: =EnergyInitialCapacity!D6*1.1 -> 8538.75
A7: Bulgaria | B7: Hydro Pump Storage | C7: =EnergyInitialCapacity!D7*1.1 -> 1649.12
A8: Switzerland | B8: Hydro Pump Storage | C8: =EnergyInitialCapacity!D8*1.1 -> 405887.9
A9: Czech R | B9: Hydro Pump Storage | C9: =EnergyInitialCapacity!D9*1.1 -> 7395.85
A10: Germany | B10: Hydro Pump Storage | C10: =EnergyInitialCapacity!D10*1.1 -> 42488.6
A11: Spain | B11: Hydro Pump Storage | C11: =EnergyInitialCapacity!D11*1.1 -> 1683166
A12: France | B12: Hydro Pump Storage | C12: =EnergyInitialCapacity!D12*1.1 -> 202725.6
A13: Great Brit. | B13: Hydro Pump Storage | C13: =EnergyInitialCapacity!D13*1.1 -> 36775.2
A14: Greece | B14: Hydro Pump Storage | C14: =EnergyInitialCapacity!D14*1.1 -> 23309.484
A15: Croatia | B15: Hydro Pump Storage | C15: =EnergyInitialCapacity!D15*1.1 -> 23309.484
... A20: Luxemb. | B20: Hydro Pump Storage | C20: =EnergyInitialCapacity!D20*1.1 -> 6732
A33: Austria | B33: Li-Ion_BESS | C33: 20000000
A34: Bosnia H | B34: Li-Ion_BESS | C34: 20000000
A35: Belgium | B35: Li-Ion_BESS | C35: 20000000
A36: Bulgaria | B36: Li-Ion_BESS | C36: 20000000
A37: Switzerland | B37: Li-Ion_BESS | C37: 20000000
A38: Czech R | B38: Li-Ion_BESS | C38: 20000000
A39: Germany | B39: Li-Ion_BESS | C39: 20000000
A40: Denmark | B40: Li-Ion_BESS | C40: 20000000
A41: Estonia | B41: Li-Ion_BESS | C41: 20000000
A42: Spain | B42: Li-Ion_BESS | C42: 20000000
A43: Finland | B43: Li-Ion_BESS | C43: 20000000
A44: France | B44: Li-Ion_BESS | C44: 20000000
... A52: Luxemb. | B52: Li-Ion_BESS | C52: 20000000

Sheet StorageInitialEnergyLevel
A1: Source: Assumed
A2: Description: Percentage of installed capacity available in first hour of a season (default: 0)
A3: StorageType | B3: StorageInitialEnergyLevel as a percentage of StorageInstalledEnergyCapacity
A4: Hydro Pump Storage | B4: 0.5
A5: Li-Ion_BESS | B5: 0.5

Sheet StorageChargeEff
A1: Source: Assumed
A2: Description: Efficiency of charging a storage (non-spillage during charging) (default: 1)
A3: StorageType | B3: storageChargeEff
A4: Hydro Pump Storage | B4: 0.8
A5: Li-Ion_BESS | B5: 0.9

Sheet StorageDischargeEff
A1: Source: Assumed
A2: Description: Efficiency of discharging a storage (non-spillage during discharging) (default: 1)
A3: StorageType | B3: storageDischargeEff
A4: Hydro Pump Storage | B4: 1
A5: Li-Ion_BESS | B5: 1

Sheet StoragePowToEnergy
A1: Source: Assumed
A2: Description: Required ratio between installed power of storage and installed energy of storage (default: 1)
A3: StorageType | B3: storageChargeEff
A4: Li-Ion_BESS | B4: 0.5

Sheet StorageBleedEfficiency
A1: Source: Assumed
A2: Description: Hourly percentage of spillage (self-discharge) of storage types (default: 1 - no self-discharge)
A3: StorageType | B3: storageBleedEff
A4: Hydro Pump Storage | B4: 1
A5: Li-Ion_BESS | B5: 1

Sheet Lifetime
A1: Source: Battery cost medish (Cole et al 2016) 2014$/kWh
A2: Description: Lifetime in years of storage type (default: 0)
A3: StorageTypes | B3: storageLifetime
A4: Hydro Pump Storage | B4: 25
A5: Li-Ion_BESS | B5: 15
